Workbook
Name _CEUS: [1]CEUS!$A$3:$C$21
Name _Plugs: '[1]CBECS-2003'!$A$3:$U$75

Sheet Space Types
A1: OS:SpaceType | N1: OS:People:Definition | AF1: OS:DesignSpecification:OutdoorAir | AR1: OS:ElectricEquipment:Definition | BB1: OS:Lights:Definition | BK1: OS:GasEquipment:Definition | BV1: OS:SpaceInfiltration:DesignFlowRate | CG1: OS:InternalMass:Definition
I2: OS:Rendering:Color | J2: OS:Rendering:Color | K2: OS:Rendering:Color | L2: OS:SpaceType | M2: OS:Schedule | P2: OS:People:Definition | U2: OS:Schedule | V2: OS:Schedule | W2: OS:Schedule | X2: OS:People:Definition | AC2: OS:People:Definition | AE2: OS:Schedule | AG2: OS:DesignSpecification:OutdoorAir | AI2: OS:DesignSpecification:OutdoorAir | AL2: OS:DesignSpecification:OutdoorAir | AQ2: OS:DesignSpecification:OutdoorAir | AS2: OS:ElectricEquipment:Definition | AT2: OS:ElectricEquipment:Definition | AU2: OS:ElectricEquipment:Definition | AV2: OS:ElectricEquipment:Definition | AZ2: OS:ElectricEquipment:Definition | BA2: OS:Schedule | BC2: OS:Lights:Definition | BD2: OS:Lights:Definition | BE2: OS:Lights:Definition | BI2: OS:Lights:Definition | BJ2: OS:Schedule | BM2: OS:GasEquipment:Definition | BN2: OS:GasEquipment:Definition | BO2: OS:GasEquipment:Definition | BP2: OS:GasEquipment:Definition | BT2: OS:GasEquipment:Definition | BU2: OS:Schedule | BW2: OS:SpaceInfiltration:DesignFlowRate | BX2: OS:SpaceInfiltration:DesignFlowRate | CC2: OS:SpaceInfiltration:DesignFlowRate | CD2: OS:Schedule | CG2: OS:InternalMass:Definition | CH2: OS:InternalMass:Definition | CI2: OS:InternalMass:Definition | CJ2: OS:Material | CK2: OS:Material | CL2: OS:Material | CM2: OS:Material | CN2: OS:Material | CO2: OS:Material | CP2: OS:Material | CQ2: OS:Material | CR2: OS:Construction and OS:Material | CW2: OS:InternalMass:Definition
A3: CATEGORY | B3: !- Standards Template | C3: !- Standards Building Type | D3: !- Standards Space Type | E3: OpenStudio_Standards.xlsx | F3: Code Year | G3: State | H3: Code | I3: !- Rendering Red Value | J3: !- Rendering Green Value | K3: !- Rendering Blue Value | L3: !- Name | M3: Schedule Set !- Name | N3: OCCUPANT DENSITY FT2/person | O3: OCCUPANT DENSITY #/1000 FT2 | P3: !- People per Space Floor Area {person/m2} | Q3: Sensible Heat Gain (Btu/h-person) | R3: Sensible Heat Gain (W/person) | S3: Latent Heat Gain (Btu/h-person) | T3: Latent Heat Gain (W/person) | U3: Summer Design Day Total Heat Gain (W/person) | V3: Winter Design Day Total Heat Gain (W/person) | W3: Default Day Total Heat Gain (W/person) | X3: !- Sensible Heat Fraction | Y3: Source_1 | Z3: Additional Info_1 | AA3: Source_2 | AB3: Additional Info_2 | AC3: !- Name | AD3: !- Number of People Schedule Name | AE3: Occupancy Activity Schedule !- Name | AF3: PEOPLE OUTDOOR AIRFLOW RATE IN BREATHING ZONE Rp CFM/PERSON | AG3: !- Outdoor Air Flow per Person {m3/s-person} | AH3: AREA OUTDOOR AIRFLOW RATE IN BREATHING ZONE Ra CFM/FT2a | AI3: !- Outdoor Air Flow per Floor Area {m3/s-m2} | AJ3: EXHAUST AIRFLOW RATE CFM/FT 2 | AK3: EXHAUST AIRFLOW RATE m3/s-m2 | AL3: !- Outdoor Air Flow Air Changes per Hour {1/hr} | AM3: Source_1 | AN3: Additional Info_1 | AO3: Source_2 | AP3: Additional Info_2 | AQ3: !- Name | AR3: Default Power Density (W/ft2) | AS3: !- Watts per Space Floor Area {W/m2} | AT3: !- Fraction Latent | AU3: !- Fraction Radiant | AV3: !- Fraction Lost | AW3: Source_1 | AX3: Source_2 | AY3: Additional Info | AZ3: !- Name | BA3: Electric Equipment Schedule | BB3: Default Power Density (W/ft2) | BC3: !- Watts per Space Floor Area {W/m2} | BD3: !- Fraction Radiant | BE3: !- Fraction Visible | BF3: Source_1 | BG3: Source_2 | BH3: Additional Info | BI3: !- Name | BJ3: Lighting Schedule | BK3: Interior Gas Appliance Power Density (W/ft2) | BL3: Interior Gas Appliance Power Density (Btu/h-ft2) | BM3: !- Power per Zone Floor Area {W/m2} | BN3: !- Fraction Latent | BO3: !- Fraction Radiant | BP3: !- Fraction Lost | BQ3: Source_1 | BR3: Source_2 | BS3: Additional Info | BT3: !- Name | BU3: Gas Equipment Schedule | BV3: Infiltration per Exterior Area (ft^3/min*ft^2 ext) | BW3: !- Air Changes per Hour {1/hr} | BX3: !- Flow per Exterior Surface Area {m3/s-m2} | BY3: Source_1 | BZ3: Additional Info_1 | CA3: Source_2 | CB3: Additional Info_2 | CC3: !- Name | CD3: Infiltration Schedule | CE3: Building Type | CF3: Space Type | CG3: !- Surface Area {m2} | CH3: !- Surface Area per Space Floor Area {dimensionless} | CI3: !- Surface Area per Person {m2/person} | CJ3: !- Roughness | CK3: !- Thickness {m} | CL3: !- Conductivity {W/m-K} | CM3: !- Density {kg/m3} | CN3: !- Specific Heat {J/kg-K} | CO3: !- Thermal Absorptance | CP3: !- Solar Absorptance | CQ3: !- Visible Absorptance | CR3: !- Name | CS3: Source_1 | CT3: Additional Info_1 | CU3: Source_2 | CV3: Additional Info_2 | CW3: !- Name
A4: d83d8e85-c973-43f1-8010-e8f36dc62725 | B4: 464b7a91-abc0-48af-b607-07922fa703df | C4: 789d7a7f-91a3-4dde-9310-9a74c14d32e5 | D4: c3101f12-7b66-41ad-90b5-0c5afec65227 | I4: bb3bf4f1-c80b-43b9-93a6-263313c59141 | J4: f48c2a4a-3151-4163-b625-b93c6c227f62 | K4: 35292a8f-2c31-428e-b12b-ecb42e41f30c | L4: c318426a-e0cf-4c00-830e-9470f81507bb | M4: 36715673-fabf-4b26-bcb3-54efccbcf6ca | P4: 1f550d2e-d956-4855-8f6c-850193633ba2 | U4: f70f21e0-e825-4f34-a3a0-3417ba47b289 | V4: 0a44a70a-025f-4b95-b067-1905cd773228 | W4: f3e926b6-9054-43e5-b214-72715fea5476 | X4: 7e5f790a-2539-4f59-b04d-75858ff1caa0 | AC4: 0e52365f-0968-4865-98c8-5a391db72fe1 | AD4: 729982cd-0e35-4f56-90dd-aa3ce52c45a4 | AE4: 7c329b17-a9b9-429d-87d6-8d696bb1a0f1 | AG4: a791e0a0-108f-4ea5-ac55-ffbc9ef41f04 | AI4: 03d16ff5-015b-4c1f-89e1-fb9e8f3c323e | AL4: 41dd9f25-8df0-46e6-9f29-cceef9210ae8 | AQ4: f8a27cd2-f746-4301-a112-59d13e40d78d | AS4: dd740279-a043-472e-9440-1247838bdebd | AT4: 93c3190c-58c6-4fa6-b31d-e972f017b622 | AU4: e7668a0e-eeeb-49fe-b68d-e4673ff0492f | AV4: 17a128c0-8bb3-42fe-8fa8-e9b6c9857c61 | AZ4: 88a913cc-2e7a-402c-8f68-e04d9aea2bfe | BA4: 922e17af-4f99-4a08-92d5-c8797f685f91 | BC4: da106b8e-74c8-48ae-9585-c42116b2ba37 | BD4: 37274c8e-ef2a-4273-be16-1568ef1010d8 | BE4: 2f6014cb-8ffd-48ef-8c06-e2f22e8f09fb | BI4: 8cd22776-3059-4312-be9f-414a4cc9a5d4 | BJ4: 06a4bb43-86fe-4d0d-b323-df7f797ddedf | BM4: 75657b05-6269-49ed-9dde-0685e47cd2e8 | BN4: d7a052b3-0fd2-4248-aceb-14699019a4a4 | BO4: fa38e540-d001-49d9-b3f1-d1a707fc1579 | BP4: 297cff0e-3751-4d1e-8c51-b492f8bae160 | BT4: 4478951e-a465-46c5-913d-bcea7a66cb2a | BU4: be6b6705-67ab-46ec-a6e5-80adf6c48c0a | BW4: 306e4282-557a-4c79-a31e-dbe513817f52 | BX4: 821df950-1005-42a1-bb71-94e21d06f843 | CC4: f0b3db32-813a-495e-9ca0-dde8056737c8 | CD4: 94e29b50-ba90-424a-98b8-c2dc37ad1d28 | CG4: 620be5d0-583e-43e9-b3de-0b70c7cf5176 | CH4: 953b161f-1acf-4fc3-a393-bdce6b3c5153 | CI4: b80aad76-63a0-4cbf-802e-5e89b172c4f9 | CJ4: 1bd0cfbf-ead3-4e72-b15b-e4980f9b59db | CK4: dc1f4078-c6b5-4ccb-a537-4da64d413107 | CL4: cff5961c-e380-4d30-9a4d-0bfdf353115f | CM4: 5a6d7588-d7ab-4a8a-be29-d0e69477a2d9 | CN4: 51ff4529-089d-43c6-90c4-e6bdcb13b9fe | CO4: dc5451c6-9cf1-4680-bb77-8c264cd2f1ec | CP4: 50e1157d-9579-4ef9-b50e-099cefad7e0f | CQ4: 2810bb86-71f1-4ece-94e6-b7427b2274ef | CR4: feb23d72-7ec3-4505-84ec-987e02009258 | CW4: 65c47774-d0bf-4ce9-ba77-1b1304459dc7
A5: BA Automotive Facility | B5: =CONCATENATE(F5,"_",G5,"_",H5) -> 2025_AU_NCC | C5: =MID(A5,4,80) -> Automotive Facility | D5: Whole Building | E5: WholeBuilding | F5: 2025 | G5: AU | H5: NCC | I5: 255 | J5: 255 | K5: 255 | L5: =CONCATENATE(A5,"_",F5,G5,H5) -> BA Automotive Facility_2025AUNCC | M5: =CONCATENATE(L5,"ScheduleSet") -> BA Automotive Facility_2025AUNCCScheduleSet | N5: 143 | O5: 6.993007 | P5: 0.075272133 | Q5: 255.91 | R5: 75 | S5: 187.67 | T5: 55 | W5: 130 | X5: 0.57692308 | Y5: NCC S35C2n | Z5: Other applications (non-dining) | AC5: =CONCATENATE(Y5,Z5,AA5,AB5,A5,"PeopleDef") -> NCC S35C2nOther applications (non-dining)BA Automotive FacilityPeopleDef | AD5: NECB-E-Occupancy | AE5: =CONCATENATE(A5,"Activity") -> BA Automotive FacilityActivity | AH5: 0.25 | AI5: =AH5*0.00508 -> 0.00127 | AM5: COMNET-REV9 | AN5: WholeBuilding | AQ5: =CONCATENATE(AM5,AN5,AO5,AP5,A5,"Vent") -> COMNET-REV9WholeBuildingBA Automotive FacilityVent | AR5: 0 | AS5: 0 | AT5: 0 | AU5: 0.5 | AV5: 0 | AW5: NCC S35C2l | AX5: NREL 956/Eley Analysis | AY5: Class 8 (Automotive/other applications) - no equipment load per S35C2l; radiant/latent/lost fraction split retained from original WA/COMNET-REV9 source (AIRAH Technical Handbook does not publish this split) | AZ5: =CONCATENATE(AW5,AX5,AY5,A5,"ElectricalEquipDef") -> NCC S35C2lNREL 956/Eley AnalysisClass 8 (Automotive/other applications) - no equipment load per S35C2l; radiant/latent/lost fraction split retained from original WA/COMNET-REV9 source (AIRAH Technical Handbook does not publish this split)BA Automotive FacilityElectricalEquipDef | BA5: NECB-E-Electric-Equipment | BB5: 0.73 | BC5: 7.85765 | BD5: 0.37 | BE5: 0.2 | BF5: IECC Table C405.3.2(1) | BH5: Automotive facility; radiant/visible fraction split retained from original WA/COMNET-REV9 source | BI5: =CONCATENATE(BF5,BG5,BH5,"LightingDef") -> IECC Table C405.3.2(1)Automotive facility; radiant/visible fraction split retained from original WA/COMNET-REV9 sourceLightingDef | BJ5: NECB-E-Lighting | BK5: 0.22081614 | BL5: 0.75342466 | BM5: 8.109863 | BN5: 0 | BO5: 0.75 | BP5: 0.25 | BQ5: COMNET-REV9 | BR5: California Commercial End-Use Survey (CEUS) | BS5: 93%ThermEffRadiant | BT5: =CONCATENATE(BQ5,BR5,BS5,A5,"GasEquipDef") -> COMNET-REV9California Commercial End-Use Survey (CEUS)93%ThermEffRadiantBA Automotive FacilityGasEquipDef | BU5: NECB-E-Electric-Equipment | BW5: 0.7 | BY5: NCC S34C2(6) | BZ5: 0.7 ACH assumed as design infiltration for periods without mechanical outdoor air supply; NCC also specifies 0.35 ACH when mechanical OA is operating (to be applied via infiltration schedule once developed) | CB5: =CONCATENATE(CE5,"_",CF5) -> Automotive facility_WholeBuilding | CC5: =CONCATENATE(BY5,BZ5,A5,"Infil") -> NCC S34C2(6)0.7 ACH assumed as design infiltration for periods without mechanical outdoor air supply; NCC also specifies 0.35 ACH when mechanical OA is operating (to be applied via infiltration schedule once developed)BA Automotive FacilityInfil | CD5: Always On | CE5: Automotive facility | CF5: WholeBuilding | CH5: 2 | CJ5: MediumSmooth | CK5: 0.15 | CL5: 0.12 | CM5: 540 | CN5: 1210 | CO5: 0.9 | CP5: 0.7 | CQ5: 0.7 | CR5: Std Wood 6inch | CS5: OpenStudio-Prototype-Buildings | CV5: =CR5 -> Std Wood 6inch | CW5: =CONCATENATE(CS5,CT5,CU5,CV5,"InternalMassDef") -> OpenStudio-Prototype-BuildingsStd Wood 6inchInternalMassDef
A6: BA Convention Center | B6: =CONCATENATE(F6,"_",G6,"_",H6) -> 2025_AU_NCC | C6: =MID(A6,4,80) -> Convention Center | D6: Whole Building | E6: WholeBuilding | F6: 2025 | G6: AU | H6: NCC | I6: 255 | J6: 255 | K6: 255 | L6: =CONCATENATE(A6,"_",F6,G6,H6) -> BA Convention Center_2025AUNCC | M6: =CONCATENATE(L6,"ScheduleSet") -> BA Convention Center_2025AUNCCScheduleSet | N6: 20 | O6: 50 | P6: 0.53819575 | Q6: 255.91 | R6: 75 | S6: 187.67 | T6: 55 | W6: 130 | X6: 0.57692308 | Y6: NCC S35C2n | Z6: Other applications (non-dining) | AC6: =CONCATENATE(Y6,Z6,AA6,AB6,A6,"PeopleDef") -> NCC S35C2nOther applications (non-dining)BA Convention CenterPeopleDef | AD6: NECB-C-Occupancy | AE6: =CONCATENATE(A6,"Activity") -> BA Convention CenterActivity | AH6: 0.31 | AI6: =AH6*0.00508 -> 0.0015748 | AM6: COMNET-REV9 | AN6: WholeBuilding | AQ6: =CONCATENATE(AM6,AN6,AO6,AP6,A6,"Vent") -> COMNET-REV9WholeBuildingBA Convention CenterVent | AR6: 0.74760799 | AS6: 8.0472524 | AT6: 0 | AU6: 0.5 | AV6: 0 | AW6: COMNET-REV9 | AX6: NREL 956/Eley Analysis | AY6: DOEPrototype | AZ6: =CONCATENATE(AW6,AX6,AY6,A6,"ElectricalEquipDef") -> COMNET-REV9NREL 956/Eley AnalysisDOEPrototypeBA Convention CenterElectricalEquipDef | BA6: NECB-C-Electric-Equipment | BB6: 0.743224 | BC6: 8 | BD6: 0.37 | BE6: 0.2 | BF6: NCC J7D3a | BH6: Auditorium, church and public hall (nearest; Class 9b conference has a special 150W/room+10W/person provision, not populated pending room-count assumption); radiant/visible fraction split retained from original WA/COMNET-REV9 source (AIRAH Technical Handbook does not publish this split) | BI6: =CONCATENATE(BF6,BG6,BH6,"LightingDef") -> NCC J7D3aAuditorium, church and public hall (nearest; Class 9b conference has a special 150W/room+10W/person provision, not populated pending room-count assumption); radiant/visible fraction split retained from original WA/COMNET-REV9 source (AIRAH Technical Handbook does not publish this split)LightingDef | BJ6: NECB-C-Lighting | BK6: 0.006691398 | BL6: 0.02283105 | BM6: 0.24575342 | BN6: 0 | BO6: 0.75 | BP6: 0.25 | BQ6: COMNET-REV9 | BR6: California Commercial End-Use Survey (CEUS) | BS6: 93%ThermEffRadiant | BT6: =CONCATENATE(BQ6,BR6,BS6,A6,"GasEquipDef") -> COMNET-REV9California Commercial End-Use Survey (CEUS)93%ThermEffRadiantBA Convention CenterGasEquipDef | BU6: NECB-C-Electric-Equipment | BW6: 0.7 | BY6: NCC S34C2(6) | BZ6: 0.7 ACH assumed as design infiltration for periods without mechanical outdoor air supply; NCC also specifies 0.35 ACH when mechanical OA is operating (to be applied via infiltration schedule once developed) | CB6: =CONCATENATE(CE6,"_",CF6) -> Convention centre_WholeBuilding | CC6: =CONCATENATE(BY6,BZ6,A6,"Infil") -> NCC S34C2(6)0.7 ACH assumed as design infiltration for periods without mechanical outdoor air supply; NCC also specifies 0.35 ACH when mechanical OA is operating (to be applied via infiltration schedule once developed)BA Convention CenterInfil | CD6: Always On | CE6: Convention centre | CF6: WholeBuilding | CH6: 2 | CJ6: MediumSmooth | CK6: 0.15 | CL6: 0.12 | CM6: 540 | CN6: 1210 | CO6: 0.9 | CP6: 0.7 | CQ6: 0.7 | CR6: Std Wood 6inch | CS6: OpenStudio-Prototype-Buildings | CV6: =CR6 -> Std Wood 6inch | CW6: =CONCATENATE(CS6,CT6,CU6,CV6,"InternalMassDef") -> OpenStudio-Prototype-BuildingsStd Wood 6inchInternalMassDef
A7: BA Courthouse | B7: =CONCATENATE(F7,"_",G7,"_",H7) -> 2025_AU_NCC | C7: =MID(A7,4,80) -> Courthouse | D7: Whole Building | E7: WholeBuilding | F7: 2025 | G7: AU | H7: NCC | I7: 255 | J7: 255 | K7: 255 | L7: =CONCATENATE(A7,"_",F7,G7,H7) -> BA Courthouse_2025AUNCC | M7: =CONCATENATE(L7,"ScheduleSet") -> BA Courthouse_2025AUNCCScheduleSet | N7: 14 | O7: 71.428571 | P7: 0.76885108 | Q7: 255.91 | R7: 75 | S7: 187.67 | T7: 55 | W7: 130 | X7: 0.57692308 | Y7: NCC S35C2n | Z7: Other applications (non-dining) | AC7: =CONCATENATE(Y7,Z7,AA7,AB7,A7,"PeopleDef") -> NCC S35C2nOther applications (non-dining)BA CourthousePeopleDef | AD7: NECB-A-Occupancy | AE7: =CONCATENATE(A7,"Activity") -> BA CourthouseActivity | AH7: 0.41 | AI7: =AH7*0.00508 -> 0.0020828 | AM7: COMNET-REV9 | AN7: WholeBuilding | AQ7: =CONCATENATE(AM7,AN7,AO7,AP7,A7,"Vent") -> COMNET-REV9WholeBuildingBA CourthouseVent | AR7: 0 | AS7: 0 | AT7: 0 | AU7: 0.5 | AV7: 0 | AW7: NCC S35C2l | AX7: NREL 956/Eley Analysis | AY7: Class 9b special (Other applications) - no equipment load per S35C2l; radiant/latent/lost fraction split retained from original WA/COMNET-REV9 source (AIRAH Technical Handbook does not publish this split) | AZ7: =CONCATENATE(AW7,AX7,AY7,A7,"ElectricalEquipDef") -> NCC S35C2lNREL 956/Eley AnalysisClass 9b special (Other applications) - no equipment load per S35C2l; radiant/latent/lost fraction split retained from original WA/COMNET-REV9 source (AIRAH Technical Handbook does not publish this split)BA CourthouseElectricalEquipDef | BA7: NECB-A-Electric-Equipment | BB7: 0.418064 | BC7: 4.5 | BD7: 0.37 | BE7: 0.2 | BF7: NCC J7D3a | BH7: Courtroom; radiant/visible fraction split retained from original WA/COMNET-REV9 source (AIRAH Technical Handbook does not publish this split) | BI7: =CONCATENATE(BF7,BG7,BH7,"LightingDef") -> NCC J7D3aCourtroom; radiant/visible fraction split retained from original WA/COMNET-REV9 source (AIRAH Technical Handbook does not publish this split)LightingDef | BJ7: NECB-A-Lighting | BK7: 0.050185486 | BL7: 0.17123288 | BM7: 1.8431507 | BN7: 0.01 | BO7: 0.4 | BP7: 0.4 | BQ7: COMNET-REV9 | BR7: California Commercial End-Use Survey (CEUS) | BS7: 60%ThermEffProcess | BT7: =CONCATENATE(BQ7,BR7,BS7,A7,"GasEquipDef") -> COMNET-REV9California Commercial End-Use Survey (CEUS)60%ThermEffProcessBA CourthouseGasEquipDef | BU7: NECB-A-Electric-Equipment | BW7: 0.7 | BY7: NCC S34C2(6) | BZ7: 0.7 ACH assumed as design infiltration for periods without mechanical outdoor air supply; NCC also specifies 0.35 ACH when mechanical OA is operating (to be applied via infiltration schedule once developed) | CB7: =CONCATENATE(CE7,"_",CF7) -> Courthouse_WholeBuilding | CC7: =CONCATENATE(BY7,BZ7,A7,"Infil") -> NCC S34C2(6)0.7 ACH assumed as design infiltration for periods without mechanical outdoor air supply; NCC also specifies 0.35 ACH when mechanical OA is operating (to be applied via infiltration schedule once developed)BA CourthouseInfil | CD7: Always On | CE7: Courthouse | CF7: WholeBuilding | CH7: 2 | CJ7: MediumSmooth | CK7: 0.15 | CL7: 0.12 | CM7: 540 | CN7: 1210 | CO7: 0.9 | CP7: 0.7 | CQ7: 0.7 | CR7: Std Wood 6inch | CS7: OpenStudio-Prototype-Buildings | CV7: =CR7 -> Std Wood 6inch | CW7: =CONCATENATE(CS7,CT7,CU7,CV7,"InternalMassDef") -> OpenStudio-Prototype-BuildingsStd Wood 6inchInternalMassDef
A8: BA Dining: Bar Lounge/Leisure | B8: =CONCATENATE(F8,"_",G8,"_",H8) -> 2025_AU_NCC | C8: =MID(A8,4,80) -> Dining: Bar Lounge/Leisure | D8: Whole Building | E8: WholeBuilding | F8: 2025 | G8: AU | H8: NCC | I8: 255 | J8: 255 | K8: 255 | L8: =CONCATENATE(A8,"_",F8,G8,H8) -> BA Dining: Bar Lounge/Leisure_2025AUNCC | M8: =CONCATENATE(L8,"ScheduleSet") -> BA Dining: Bar Lounge/Leisure_2025AUNCCScheduleSet | N8: 10 | O8: 100 | P8: 1.0763915 | Q8: 272.97 | R8: 80 | S8: 272.97 | T8: 80 | W8: 160 | X8: 0.5 | Y8: NCC S35C2n | Z8: Dining room/restaurant/cafe | AC8: =CONCATENATE(Y8,Z8,AA8,AB8,A8,"PeopleDef") -> NCC S35C2nDining room/restaurant/cafeBA Dining: Bar Lounge/LeisurePeopleDef | AD8: NECB-B-Occupancy | AE8: =CONCATENATE(A8,"Activity") -> BA Dining: Bar Lounge/LeisureActivity | AH8: 0.93 | AI8: =AH8*0.00508 -> 0.0047244 | AM8: COMNET-REV9 | AN8: WholeBuilding | AQ8: =CONCATENATE(AM8,AN8,AO8,AP8,A8,"Vent") -> COMNET-REV9WholeBuildingBA Dining: Bar Lounge/LeisureVent | AR8: 0.464515 | AS8: 5 | AT8: 0 | AU8: 0.5 | AV8: 0 | AW8: NCC S35C2l | AX8: NREL 956/Eley Analysis | AY8: Class 6 cafe/restaurant; radiant/latent/lost fraction split retained from original WA/COMNET-REV9 source (AIRAH Technical Handbook does not publish this split) | AZ8: =CONCATENATE(AW8,AX8,AY8,A8,"ElectricalEquipDef") -> NCC S35C2lNREL 956/Eley AnalysisClass 6 cafe/restaurant; radiant/latent/lost fraction split retained from original WA/COMNET-REV9 source (AIRAH Technical Handbook does not publish this split)BA Dining: Bar Lounge/LeisureElectricalEquipDef | BA8: NECB-B-Electric-Equipment | BB8: 1.300643 | BC8: 14 | BD8: 0.37 | BE8: 0.2 | BF8: NCC J7D3a | BH8: Restaurant, cafe, bar, hotel lounge...; radiant/visible fraction split retained from original WA/COMNET-REV9 source (AIRAH Technical Handbook does not publish this split) | BI8: =CONCATENATE(BF8,BG8,BH8,"LightingDef") -> NCC J7D3aRestaurant, cafe, bar, hotel lounge...; radiant/visible fraction split retained from original WA/COMNET-REV9 source (AIRAH Technical Handbook does not publish this split)LightingDef | BJ8: NECB-B-Lighting | BK8: 5.1389937 | BL8: 17.534247 | BM8: 188.73863 | BN8: 0 | BO8: 0.75 | BP8: 0.25 | BQ8: COMNET-REV9 | BR8: California Commercial End-Use Survey (CEUS) | BS8: 93%ThermEffRadiant | BT8: =CONCATENATE(BQ8,BR8,BS8,A8,"GasEquipDef") -> COMNET-REV9California Commercial End-Use Survey (CEUS)93%ThermEffRadiantBA Dining: Bar Lounge/LeisureGasEquipDef | BU8: RestaurantFastFood BLDG_EQUIP_SCH | BW8: 0.7 | BY8: NCC S34C2(6) | BZ8: 0.7 ACH assumed as design infiltration for periods without mechanical outdoor air supply; NCC also specifies 0.35 ACH when mechanical OA is operating (to be applied via infiltration schedule once developed) | CB8: =CONCATENATE(CE8,"_",CF8) -> Dining - bar/lounge_WholeBuilding | CC8: =CONCATENATE(BY8,BZ8,A8,"Infil") -> NCC S34C2(6)0.7 ACH assumed as design infiltration for periods without mechanical outdoor air supply; NCC also specifies 0.35 ACH when mechanical OA is operating (to be applied via infiltration schedule once developed)BA Dining: Bar Lounge/LeisureInfil | CD8: Always On | CE8: Dining - bar/lounge | CF8: WholeBuilding | CH8: 2 | CJ8: MediumSmooth | CK8: 0.15 | CL8: 0.12 | CM8: 540 | CN8: 1210 | CO8: 0.9 | CP8: 0.7 | CQ8: 0.7 | CR8: Std Wood 6inch | CS8: OpenStudio-Prototype-Buildings | CV8: =CR8 -> Std Wood 6inch | CW8: =CONCATENATE(CS8,CT8,CU8,CV8,"InternalMassDef") -> OpenStudio-Prototype-BuildingsStd Wood 6inchInternalMassDef
A9: BA Dining: Cafeteria/Fast Food | B9: =CONCATENATE(F9,"_",G9,"_",H9) -> 2025_AU_NCC | C9: =MID(A9,4,80) -> Dining: Cafeteria/Fast Food | D9: Whole Building | E9: WholeBuilding | F9: 2025 | G9: AU | H9: NCC | I9: 255 | J9: 255 | K9: 255 | L9: =CONCATENATE(A9,"_",F9,G9,H9) -> BA Dining: Cafeteria/Fast Food_2025AUNCC | M9: =CONCATENATE(L9,"ScheduleSet") -> BA Dining: Cafeteria/Fast Food_2025AUNCCScheduleSet | N9: 10 | O9: 100 | P9: 1.0763915 | Q9: 272.97 | R9: 80 | S9: 272.97 | T9: 80 | W9: 160 | X9: 0.5 | Y9: NCC S35C2n | Z9: Dining room/restaurant/cafe | AC9: =CONCATENATE(Y9,Z9,AA9,AB9,A9,"PeopleDef") -> NCC S35C2nDining room/restaurant/cafeBA Dining: Cafeteria/Fast FoodPeopleDef | AD9: NECB-B-Occupancy | AE9: =CONCATENATE(A9,"Activity") -> BA Dining: Cafeteria/Fast FoodActivity | AH9: 0.93 | AI9: =AH9*0.00508 -> 0.0047244 | AM9: COMNET-REV9 | AN9: WholeBuilding | AQ9: =CONCATENATE(AM9,AN9,AO9,AP9,A9,"Vent") -> COMNET-REV9WholeBuildingBA Dining: Cafeteria/Fast FoodVent | AR9: 0.464515 | AS9: 5 | AT9: 0 | AU9: 0.5 | AV9: 0 | AW9: NCC S35C2l | AX9: NREL 956/Eley Analysis | AY9: Class 6 cafe/restaurant; radiant/latent/lost fraction split retained from original WA/COMNET-REV9 source (AIRAH Technical Handbook does not publish this split) | AZ9: =CONCATENATE(AW9,AX9,AY9,A9,"ElectricalEquipDef") -> NCC S35C2lNREL 956/Eley AnalysisClass 6 cafe/restaurant; radiant/latent/lost fraction split retained from original WA/COMNET-REV9 source (AIRAH Technical Handbook does not publish this split)BA Dining: Cafeteria/Fast FoodElectricalEquipDef | BA9: NECB-B-Electric-Equipment | BB9: 1.300643 | BC9: 14 | BD9: 0.37 | BE9: 0.2 | BF9: NCC J7D3a | BH9: Restaurant, cafe, bar, hotel lounge...; radiant/visible fraction split retained from original WA/COMNET-REV9 source (AIRAH Technical Handbook does not publish this split) | BI9: =CONCATENATE(BF9,BG9,BH9,"LightingDef") -> NCC J7D3aRestaurant, cafe, bar, hotel lounge...; radiant/visible fraction split retained from original WA/COMNET-REV9 source (AIRAH Technical Handbook does not publish this split)LightingDef | BJ9: NECB-B-Lighting | BK9: 5.1389937 | BL9: 17.534247 | BM9: 188.73863 | BN9: 0 | BO9: 0.75 | BP9: 0.25 | BQ9: COMNET-REV9 | BR9: California Commercial End-Use Survey (CEUS) | BS9: 93%ThermEffRadiant | BT9: =CONCATENATE(BQ9,BR9,BS9,A9,"GasEquipDef") -> COMNET-REV9California Commercial End-Use Survey (CEUS)93%ThermEffRadiantBA Dining: Cafeteria/Fast FoodGasEquipDef | BU9: RestaurantFastFood BLDG_EQUIP_SCH | BW9: 0.7 | BY9: NCC S34C2(6) | BZ9: 0.7 ACH assumed as design infiltration for periods without mechanical outdoor air supply; NCC also specifies 0.35 ACH when mechanical OA is operating (to be applied via infiltration schedule once developed) | CB9: =CONCATENATE(CE9,"_",CF9) -> Dining - cafeteria_WholeBuilding | CC9: =CONCATENATE(BY9,BZ9,A9,"Infil") -> NCC S34C2(6)0.7 ACH assumed as design infiltration for periods without mechanical outdoor air supply; NCC also specifies 0.35 ACH when mechanical OA is operating (to be applied via infiltration schedule once developed)BA Dining: Cafeteria/Fast FoodInfil | CD9: Always On | CE9: Dining - cafeteria | CF9: WholeBuilding | CH9: 2 | CJ9: MediumSmooth | CK9: 0.15 | CL9: 0.12 | CM9: 540 | CN9: 1210 | CO9: 0.9 | CP9: 0.7 | CQ9: 0.7 | CR9: Std Wood 6inch | CS9: OpenStudio-Prototype-Buildings | CV9: =CR9 -> Std Wood 6inch | CW9: =CONCATENATE(CS9,CT9,CU9,CV9,"InternalMassDef") -> OpenStudio-Prototype-BuildingsStd Wood 6inchInternalMassDef
A10: BA Dining: Family | B10: =CONCATENATE(F10,"_",G10,"_",H10) -> 2025_AU_NCC | C10: =MID(A10,4,80) -> Dining: Family | D10: Whole Building | E10: WholeBuilding | F10: 2025 | G10: AU | H10: NCC | I10: 255 | J10: 255 | K10: 255 | L10: =CONCATENATE(A10,"_",F10,G10,H10) -> BA Dining: Family_2025AUNCC | M10: =CONCATENATE(L10,"ScheduleSet") -> BA Dining: Family_2025AUNCCScheduleSet | N10: 14 | O10: 71.428571 | P10: 0.76885108 | Q10: 272.97 | R10: 80 | S10: 272.97 | T10: 80 | W10: 160 | X10: 0.5 | Y10: NCC S35C2n | Z10: Dining room/restaurant/cafe | AC10: =CONCATENATE(Y10,Z10,AA10,AB10,A10,"PeopleDef") -> NCC S35C2nDining room/restaurant/cafeBA Dining: FamilyPeopleDef | AD10: NECB-B-Occupancy | AE10: =CONCATENATE(A10,"Activity") -> BA Dining: FamilyActivity | AH10: 0.71 | AI10: =AH10*0.00508 -> 0.0036068 | AM10: COMNET-REV9 | AN10: WholeBuilding | AQ10: =CONCATENATE(AM10,AN10,AO10,AP10,A10,"Vent") -> COMNET-REV9WholeBuildingBA Dining: FamilyVent | AR10: 0.464515 | AS10: 5 | AT10: 0 | AU10: 0.5 | AV10: 0 | AW10: NCC S35C2l | AX10: NREL 956/Eley Analysis | AY10: Class 6 cafe/restaurant; radiant/latent/lost fraction split retained from original WA/COMNET-REV9 source (AIRAH Technical Handbook does not publish this split) | AZ10: =CONCATENATE(AW10,AX10,AY10,A10,"ElectricalEquipDef") -> NCC S35C2lNREL 956/Eley AnalysisClass 6 cafe/restaurant; radiant/latent/lost fraction split retained from original WA/COMNET-REV9 source (AIRAH Technical Handbook does not publish this split)BA Dining: FamilyElectricalEquipDef | BA10: NECB-B-Electric-Equipment | BB10: 1.300643 | BC10: 14 | BD10: 0.37 | BE10: 0.2 | BF10: NCC J7D3a | BH10: Restaurant, cafe, bar, hotel lounge...; radiant/visible fraction split retained from original WA/COMNET-REV9 source (AIRAH Technical Handbook does not publish this split) | BI10: =CONCATENATE(BF10,BG10,BH10,"LightingDef") -> NCC J7D3aRestaurant, cafe, bar, hotel lounge...; radiant/visible fraction split retained from original WA/COMNET-REV9 source (AIRAH Technical Handbook does not publish this split)LightingDef | BJ10: NECB-B-Lighting | BK10: 5.1389937 | BL10: 17.534247 | BM10: 188.73863 | BN10: 0.05 | BO10: 0.4 | BP10: 0.4 | BQ10: COMNET-REV9 | BR10: California Commercial End-Use Survey (CEUS) | BS10: 60%ThermEffProcess | BT10: =CONCATENATE(BQ10,BR10,BS10,A10,"GasEquipDef") -> COMNET-REV9California Commercial End-Use Survey (CEUS)60%ThermEffProcessBA Dining: FamilyGasEquipDef | BU10: RestaurantSitDown BLDG_EQUIP_SCH | BW10: 0.7 | BY10: NCC S34C2(6) | BZ10: 0.7 ACH assumed as design infiltration for periods without mechanical outdoor air supply; NCC also specifies 0.35 ACH when mechanical OA is operating (to be applied via infiltration schedule once developed) | CB10: =CONCATENATE(CE10,"_",CF10) -> Dining - family_WholeBuilding | CC10: =CONCATENATE(BY10,BZ10,A10,"Infil") -> NCC S34C2(6)0.7 ACH assumed as design infiltration for periods without mechanical outdoor air supply; NCC also specifies 0.35 ACH when mechanical OA is operating (to be applied via infiltration schedule once developed)BA Dining: FamilyInfil | CD10: Always On | CE10: Dining - family | CF10: WholeBuilding | CH10: 2 | CJ10: MediumSmooth | CK10: 0.15 | CL10: 0.12 | CM10: 540 | CN10: 1210 | CO10: 0.9 | CP10: 0.7 | CQ10: 0.7 | CR10: Std Wood 6inch | CS10: OpenStudio-Prototype-Buildings | CV10: =CR10 -> Std Wood 6inch | CW10: =CONCATENATE(CS10,CT10,CU10,CV10,"InternalMassDef") -> OpenStudio-Prototype-BuildingsStd Wood 6inchInternalMassDef
A11: BA Dormitory | B11: =CONCATENATE(F11,"_",G11,"_",H11) -> 2025_AU_NCC | C11: =MID(A11,4,80) -> Dormitory | D11: Whole Building | E11: WholeBuilding | F11: 2025 | G11: AU | H11: NCC | I11: 255 | J11: 255 | K11: 255 | L11: =CONCATENATE(A11,"_",F11,G11,H11) -> BA Dormitory_2025AUNCC | M11: =CONCATENATE(L11,"ScheduleSet") -> BA Dormitory_2025AUNCCScheduleSet | N11: 100 | O11: 10 | P11: 0.10763915 | Q11: 255.91 | R11: 75 | S11: 187.67 | T11: 55 | W11: 130 | X11: 0.57692308 | Y11: NCC S35C2n | Z11: Other applications (non-dining) | AC11: =CONCATENATE(Y11,Z11,AA11,AB11,A11,"PeopleDef") -> NCC S35C2nOther applications (non-dining)BA DormitoryPeopleDef | AD11: NECB-G-Occupancy | AE11: =CONCATENATE(A11,"Activity") -> BA DormitoryActivity | AH11: 0.11 | AI11: =AH11*0.00508 -> 0.0005588 | AM11: COMNET-REV9 | AN11: WholeBuilding | AQ11: =CONCATENATE(AM11,AN11,AO11,AP11,A11,"Vent") -> COMNET-REV9WholeBuildingBA DormitoryVent | AR11: 0 | AS11: 0 | AT11: 0 | AU11: 0.5 | AV11: 0 | AW11: NCC S35C2l | AX11: NREL 956/Eley Analysis | AY11: Class 3 dormitories - no load per S35C2l; radiant/latent/lost fraction split retained from original WA/COMNET-REV9 source (AIRAH Technical Handbook does not publish this split) | AZ11: =CONCATENATE(AW11,AX11,AY11,A11,"ElectricalEquipDef") -> NCC S35C2lNREL 956/Eley AnalysisClass 3 dormitories - no load per S35C2l; radiant/latent/lost fraction split retained from original WA/COMNET-REV9 source (AIRAH Technical Handbook does not publish this split)BA DormitoryElectricalEquipDef | BA11: NECB-G-Electric-Equipment | BB11: 0.371612 | BC11: 4 | BD11: 0.37 | BE11: 0.2 | BF11: NCC J7D3a | BH11: Dormitory of a Class 3 building used for sleeping and study; radiant/visible fraction split retained from original WA/COMNET-REV9 source (AIRAH Technical Handbook does not publish this split) | BI11: =CONCATENATE(BF11,BG11,BH11,"LightingDef") -> NCC J7D3aDormitory of a Class 3 building used for sleeping and study; radiant/visible fraction split retained from original WA/COMNET-REV9 source (AIRAH Technical Handbook does not publish this split)LightingDef | BJ11: NECB-G-Lighting | BK11: 0.20408764 | BL11: 0.69634703 | BM11: 7.4954795 | BN11: 0.01 | BO11: 0.4 | BP11: 0.4 | BQ11: COMNET-REV9 | BR11: California Commercial End-Use Survey (CEUS) | BS11: 60%ThermEffProcess | BT11: =CONCATENATE(BQ11,BR11,BS11,A11,"GasEquipDef") -> COMNET-REV9California Commercial End-Use Survey (CEUS)60%ThermEffProcessBA DormitoryGasEquipDef | BU11: ApartmentMidRise EQP_APT_SCH | BW11: 0.7 | BY11: NCC S34C2(6) | BZ11: 0.7 ACH assumed as design infiltration for periods without mechanical outdoor air supply; NCC also specifies 0.35 ACH when mechanical OA is operating (to be applied via infiltration schedule once developed) | CB11: =CONCATENATE(CE11,"_",CF11) -> Dormitory_WholeBuilding | CC11: =CONCATENATE(BY11,BZ11,A11,"Infil") -> NCC S34C2(6)0.7 ACH assumed as design infiltration for periods without mechanical outdoor air supply; NCC also specifies 0.35 ACH when mechanical OA is operating (to be applied via infiltration schedule once developed)BA DormitoryInfil | CD11: Always On | CE11: Dormitory | CF11: WholeBuilding | CH11: 2 | CJ11: MediumSmooth | CK11: 0.15 | CL11: 0.12 | CM11: 540 | CN11: 1210 | CO11: 0.9 | CP11: 0.7 | CQ11: 0.7 | CR11: Std Wood 6inch | CS11: OpenStudio-Prototype-Buildings | CV11: =CR11 -> Std Wood 6inch | CW11: =CONCATENATE(CS11,CT11,CU11,CV11,"InternalMassDef") -> OpenStudio-Prototype-BuildingsStd Wood 6inchInternalMassDef
A12: BA Exercise Center | B12: =CONCATENATE(F12,"_",G12,"_",H12) -> 2025_AU_NCC | C12: =MID(A12,4,80) -> Exercise Center | D12: Whole Building | E12: WholeBuilding | F12: 2025 | G12: AU | H12: NCC | I12: 255 | J12: 255 | K12: 255 | L12: =CONCATENATE(A12,"_",F12,G12,H12) -> BA Exercise Center_2025AUNCC | M12: =CONCATENATE(L12,"ScheduleSet") -> BA Exercise Center_2025AUNCCScheduleSet | N12: 100 | O12: 10 | P12: 0.10763915 | Q12: 255.91 | R12: 75 | S12: 187.67 | T12: 55 | W12: 130 | X12: 0.57692308 | Y12: NCC S35C2n | Z12: Other applications (non-dining) | AC12: =CONCATENATE(Y12,Z12,AA12,AB12,A12,"PeopleDef") -> NCC S35C2nOther applications (non-dining)BA Exercise CenterPeopleDef | AD12: NECB-B-Occupancy | AE12: =CONCATENATE(A12,"Activity") -> BA Exercise CenterActivity | AH12: 0.26 | AI12: =AH12*0.00508 -> 0.0013208 | AM12: COMNET-REV9 | AN12: WholeBuilding | AQ12: =CONCATENATE(AM12,AN12,AO12,AP12,A12,"Vent") -> COMNET-REV9WholeBuildingBA Exercise CenterVent | AR12: 0 | AS12: 0 | AT12: 0 | AU12: 0.5 | AV12: 0 | AW12: NCC S35C2l | AX12: NREL 956/Eley Analysis | AY12: Class 9b (Other applications) - no equipment load per S35C2l; radiant/latent/lost fraction split retained from original WA/COMNET-REV9 source (AIRAH Technical Handbook does not publish this split) | AZ12: =CONCATENATE(AW12,AX12,AY12,A12,"ElectricalEquipDef") -> NCC S35C2lNREL 956/Eley AnalysisClass 9b (Other applications) - no equipment load per S35C2l; radiant/latent/lost fraction split retained from original WA/COMNET-REV9 source (AIRAH Technical Handbook does not publish this split)BA Exercise CenterElectricalEquipDef | BA12: NECB-B-Electric-Equipment | BB12: 0.72 | BC12: 7.75002 | BD12: 0.37 | BE12: 0.2 | BF12: IECC Table C405.3.2(1) | BH12: Exercise center; radiant/visible fraction split retained from original WA/COMNET-REV9 source | BI12: =CONCATENATE(BF12,BG12,BH12,"LightingDef") -> IECC Table C405.3.2(1)Exercise center; radiant/visible fraction split retained from original WA/COMNET-REV9 sourceLightingDef | BJ12: NECB-B-Lighting | BK12: 0.006691398 | BL12: 0.02283105 | BM12: 0.24575342 | BN12: 0.05 | BO12: 0.4 | BP12: 0.4 | BQ12: COMNET-REV9 | BR12: California Commercial End-Use Survey (CEUS) | BS12: 60%ThermEffProcess | BT12: =CONCATENATE(BQ12,BR12,BS12,A12,"GasEquipDef") -> COMNET-REV9California Commercial End-Use Survey (CEUS)60%ThermEffProcessBA Exercise CenterGasEquipDef | BU12: HotelSmall ExerciseCenter_Eqp_Sch | BW12: 0.7 | BY12: NCC S34C2(6) | BZ12: 0.7 ACH assumed as design infiltration for periods without mechanical outdoor air supply; NCC also specifies 0.35 ACH when mechanical OA is operating (to be applied via infiltration schedule once developed) | CB12: =CONCATENATE(CE12,"_",CF12) -> Exercise centre_WholeBuilding | CC12: =CONCATENATE(BY12,BZ12,A12,"Infil") -> NCC S34C2(6)0.7 ACH assumed as design infiltration for periods without mechanical outdoor air supply; NCC also specifies 0.35 ACH when mechanical OA is operating (to be applied via infiltration schedule once developed)BA Exercise CenterInfil | CD12: Always On | CE12: Exercise centre | CF12: WholeBuilding | CH12: 2 | CJ12: MediumSmooth | CK12: 0.15 | CL12: 0.12 | CM12: 540 | CN12: 1210 | CO12: 0.9 | CP12: 0.7 | CQ12: 0.7 | CR12: Std Wood 6inch | CS12: OpenStudio-Prototype-Buildings | CV12: =CR12 -> Std Wood 6inch | CW12: =CONCATENATE(CS12,CT12,CU12,CV12,"InternalMassDef") -> OpenStudio-Prototype-BuildingsStd Wood 6inchInternalMassDef
A13: BA Fire Station | B13: =CONCATENATE(F13,"_",G13,"_",H13) -> 2025_AU_NCC | C13: =MID(A13,4,80) -> Fire Station | D13: Whole Building | E13: WholeBuilding | F13: 2025 | G13: AU | H13: NCC | I13: 255 | J13: 255 | K13: 255 | L13: =CONCATENATE(A13,"_",F13,G13,H13) -> BA Fire Station_2025AUNCC | M13: =CONCATENATE(L13,"ScheduleSet") -> BA Fire Station_2025AUNCCScheduleSet | N13: 33 | O13: 30.30303 | P13: 0.32617924 | Q13: 255.91 | R13: 75 | S13: 187.67 | T13: 55 | W13: 130 | X13: 0.57692308 | Y13: NCC S35C2n | Z13: Other applications (non-dining) | AC13: =CONCATENATE(Y13,Z13,AA13,AB13,A13,"PeopleDef") -> NCC S35C2nOther applications (non-dining)BA Fire StationPeopleDef | AD13: NECB-F-Occupancy | AE13: =CONCATENATE(A13,"Activity") -> BA Fire StationActivity | AH13: 0.21 | AI13: =AH13*0.00508 -> 0.0010668 | AM13: COMNET-REV9 | AN13: WholeBuilding | AQ13: =CONCATENATE(AM13,AN13,AO13,AP13,A13,"Vent") -> COMNET-REV9WholeBuildingBA Fire StationVent | AR13: 0.30658 | AS13: 3.3 | AT13: 0 | AU13: 0.5 | AV13: 0 | AW13: NCC S35C2l | AX13: NREL 956/Eley Analysis | AY13: AUTHOR-ASSUMED area-weighted composite (not a direct NCC table value) - Fire Station is not a single NCC building class, decomposed as: Apparatus Bay / Garage (Class 7a/8-like) 45%; Sleeping Quarters (Class 3 dormitory-style, sleeping only) 25%; Office / Admin / Dayroom (Class 5) 30%. Equipment W/m2 per component per S35C2l, blended by area fraction. Adjust fractions to match actual floor plan; radiant/latent/lost fraction split retained from original WA/COMNET-REV9 source (AIRAH Technical Handbook does not publish this split) | AZ13: =CONCATENATE(AW13,AX13,AY13,A13,"ElectricalEquipDef") -> NCC S35C2lNREL 956/Eley AnalysisAUTHOR-ASSUMED area-weighted composite (not a direct NCC table value) - Fire Station is not a single NCC building class, decomposed as: Apparatus Bay / Garage (Class 7a/8-like) 45%; Sleeping Quarters (Class 3 dormitory-style, sleeping only) 25%; Office / Admin / Dayroom (Class 5) 30%. Equipment W/m2 per component per S35C2l, blended by area fraction. Adjust fractions to match actual floor plan; radiant/latent/lost fraction split retained from original WA/COMNET-REV9 source (AIRAH Technical Handbook does not publish this split)BA Fire StationElectricalEquipDef | BA13: NECB-F-Electric-Equipment | BB13: 0.278709 | BC13: 3 | BD13: 0.37 | BE13: 0.2 | BF13: NCC J7D3a | BH13: AUTHOR-ASSUMED area-weighted composite (not a direct NCC table value) - Apparatus Bay / Garage (Class 7a/8-like) 45% -> Carpark - general (nearest available proxy; NCC has no vehicle-bay-specific lighting row) (2.0 W/m2); Sleeping Quarters (Class 3 dormitory-style, sleeping only) 25% -> Dormitory of a Class 3 building used for sleeping only (3.0 W/m2); Office / Admin / Dayroom (Class 5) 30% -> Office - artificially lit to >= 200 lux (4.5 W/m2). Adjust fractions to match actual floor plan; radiant/latent/lost fraction split retained from original WA/COMNET-REV9 source (AIRAH Technical Handbook does not publish this split) | BI13: =CONCATENATE(BF13,BG13,BH13,"LightingDef") -> NCC J7D3aAUTHOR-ASSUMED area-weighted composite (not a direct NCC table value) - Apparatus Bay / Garage (Class 7a/8-like) 45% -> Carpark - general (nearest available proxy; NCC has no vehicle-bay-specific lighting row) (2.0 W/m2); Sleeping Quarters (Class 3 dormitory-style, sleeping only) 25% -> Dormitory of a Class 3 building used for sleeping only (3.0 W/m2); Office / Admin / Dayroom (Class 5) 30% -> Office - artificially lit to >= 200 lux (4.5 W/m2). Adjust fractions to match actual floor plan; radiant/latent/lost fraction split retained from original WA/COMNET-REV9 source (AIRAH Technical Handbook does not publish this split)LightingDef | BJ13: NECB-F-Lighting | BK13: 0.22081614 | BL13: 0.75342466 | BM13: 8.109863 | BN13: 0 | BO13: 0.75 | BP13: 0.25 | BQ13: COMNET-REV9 | BR13: California Commercial End-Use Survey (CEUS) | BS13: 93%ThermEffRadiant | BT13: =CONCATENATE(BQ13,BR13,BS13,A13,"GasEquipDef") -> COMNET-REV9California Commercial End-Use Survey (CEUS)93%ThermEffRadiantBA Fire StationGasEquipDef | BU13: NECB-F-Electric-Equipment | BW13: 0.7 | BY13: NCC S34C2(6) | BZ13: 0.7 ACH assumed as design infiltration for periods without mechanical outdoor air supply; NCC also specifies 0.35 ACH when mechanical OA is operating (to be applied via infiltration schedule once developed) | CB13: =CONCATENATE(CE13,"_",CF13) -> Fire station_WholeBuilding | CC13: =CONCATENATE(BY13,BZ13,A13,"Infil") -> NCC S34C2(6)0.7 ACH assumed as design infiltration for periods without mechanical outdoor air supply; NCC also specifies 0.35 ACH when mechanical OA is operating (to be applied via infiltration schedule once developed)BA Fire StationInfil | CD13: Always On | CE13: Fire station | CF13: WholeBuilding | CH13: 2 | CJ13: MediumSmooth | CK13: 0.15 | CL13: 0.12 | CM13: 540 | CN13: 1210 | CO13: 0.9 | CP13: 0.7 | CQ13: 0.7 | CR13: Std Wood 6inch | CS13: OpenStudio-Prototype-Buildings | CV13: =CR13 -> Std Wood 6inch | CW13: =CONCATENATE(CS13,CT13,CU13,CV13,"InternalMassDef") -> OpenStudio-Prototype-BuildingsStd Wood 6inchInternalMassDef
A14: BA Gymnasium | B14: =CONCATENATE(F14,"_",G14,"_",H14) -> 2025_AU_NCC | C14: =MID(A14,4,80) -> Gymnasium | D14: Whole Building | E14: WholeBuilding | F14: 2025 | G14: AU | H14: NCC | I14: 255 | J14: 255 | K14: 255 | L14: =CONCATENATE(A14,"_",F14,G14,H14) -> BA Gymnasium_2025AUNCC | M14: =CONCATENATE(L14,"ScheduleSet") -> BA Gymnasium_2025AUNCCScheduleSet | N14: 33 | O14: 30.30303 | P14: 0.32617924 | Q14: 255.91 | R14: 75 | S14: 187.67 | T14: 55 | W14: 130 | X14: 0.57692308 | Y14: NCC S35C2n | Z14: Other applications (non-dining) | AC14: =CONCATENATE(Y14,Z14,AA14,AB14,A14,"PeopleDef") -> NCC S35C2nOther applications (non-dining)BA GymnasiumPeopleDef | AD14: NECB-B-Occupancy | AE14: =CONCATENATE(A14,"Activity") -> BA GymnasiumActivity | AH14: 0.3 | AI14: =AH14*0.00508 -> 0.001524 | AM14: COMNET-REV9 | AN14: WholeBuilding | AQ14: =CONCATENATE(AM14,AN14,AO14,AP14,A14,"Vent") -> COMNET-REV9WholeBuildingBA GymnasiumVent | AR14: 0 | AS14: 0 | AT14: 0 | AU14: 0.5 | AV14: 0 | AW14: NCC S35C2l | AX14: NREL 956/Eley Analysis | AY14: Class 9b (Other applications) - no equipment load per S35C2l; radiant/latent/lost fraction split retained from original WA/COMNET-REV9 source (AIRAH Technical Handbook does not publish this split) | AZ14: =CONCATENATE(AW14,AX14,AY14,A14,"ElectricalEquipDef") -> NCC S35C2lNREL 956/Eley AnalysisClass 9b (Other applications) - no equipment load per S35C2l; radiant/latent/lost fraction split retained from original WA/COMNET-REV9 source (AIRAH Technical Handbook does not publish this split)BA GymnasiumElectricalEquipDef | BA14: NECB-B-Electric-Equipment | BB14: 0.75 | BC14: 8.07293 | BD14: 0.37 | BE14: 0.2 | BF14: IECC Table C405.3.2(1) | BH14: Gymnasium; radiant/visible fraction split retained from original WA/COMNET-REV9 source | BI14: =CONCATENATE(BF14,BG14,BH14,"LightingDef") -> IECC Table C405.3.2(1)Gymnasium; radiant/visible fraction split retained from original WA/COMNET-REV9 sourceLightingDef | BJ14: NECB-B-Lighting | BK14: 0.006691398 | BL14: 0.02283105 | BM14: 0.24575342 | BN14: 0 | BO14: 0.75 | BP14: 0.25 | BQ14: COMNET-REV9 | BR14: California Commercial End-Use Survey (CEUS) | BS14: 93%ThermEffRadiant | BT14: =CONCATENATE(BQ14,BR14,BS14,A14,"GasEquipDef") -> COMNET-REV9California Commercial End-Use Survey (CEUS)93%ThermEffRadiantBA GymnasiumGasEquipDef | BU14: SchoolSecondary BLDG_EQUIP_SCH | BW14: 0.7 | BY14: NCC S34C2(6) | BZ14: 0.7 ACH assumed as design infiltration for periods without mechanical outdoor air supply; NCC also specifies 0.35 ACH when mechanical OA is operating (to be applied via infiltration schedule once developed) | CB14: =CONCATENATE(CE14,"_",CF14) -> Gymnasium_WholeBuilding | CC14: =CONCATENATE(BY14,BZ14,A14,"Infil") -> NCC S34C2(6)0.7 ACH assumed as design infiltration for periods without mechanical outdoor air supply; NCC also specifies 0.35 ACH when mechanical OA is operating (to be applied via infiltration schedule once developed)BA GymnasiumInfil | CD14: Always On | CE14: Gymnasium | CF14: WholeBuilding | CH14: 2 | CJ14: MediumSmooth | CK14: 0.15 | CL14: 0.12 | CM14: 540 | CN14: 1210 | CO14: 0.9 | CP14: 0.7 | CQ14: 0.7 | CR14: Std Wood 6inch | CS14: OpenStudio-Prototype-Buildings | CV14: =CR14 -> Std Wood 6inch | CW14: =CONCATENATE(CS14,CT14,CU14,CV14,"InternalMassDef") -> OpenStudio-Prototype-BuildingsStd Wood 6inchInternalMassDef
A15: BA Healthcare Clinic | B15: =CONCATENATE(F15,"_",G15,"_",H15) -> 2025_AU_NCC | C15: =MID(A15,4,80) -> Healthcare Clinic | D15: Whole Building | E15: WholeBuilding | F15: 2025 | G15: AU | H15: NCC | I15: 255 | J15: 255 | K15: 255 | L15: =CONCATENATE(A15,"_",F15,G15,H15) -> BA Healthcare Clinic_2025AUNCC | M15: =CONCATENATE(L15,"ScheduleSet") -> BA Healthcare Clinic_2025AUNCCScheduleSet | N15: 200 | O15: 5 | P15: 0.053819575 | Q15: 255.91 | R15: 75 | S15: 187.67 | T15: 55 | W15: 130 | X15: 0.57692308 | Y15: NCC S35C2n | Z15: Other applications (non-dining) | AC15: =CONCATENATE(Y15,Z15,AA15,AB15,A15,"PeopleDef") -> NCC S35C2nOther applications (non-dining)BA Healthcare ClinicPeopleDef | AD15: NECB-A-Occupancy | AE15: =CONCATENATE(A15,"Activity") -> BA Healthcare ClinicActivity | AH15: 0.47 | AI15: =AH15*0.00508 -> 0.0023876 | AM15: COMNET-REV9 | AN15: WholeBuilding | AQ15: =CONCATENATE(AM15,AN15,AO15,AP15,A15,"Vent") -> COMNET-REV9WholeBuildingBA Healthcare ClinicVent | AR15: 1.393546 | AS15: 15 | AT15: 0 | AU15: 0.5 | AV15: 0 | AW15: NCC S35C2l | AX15: NREL 956/Eley Analysis | AY15: Class 9a clinic/day surgery/procedure unit; radiant/latent/lost fraction split retained from original WA/COMNET-REV9 source (AIRAH Technical Handbook does not publish this split) | AZ15: =CONCATENATE(AW15,AX15,AY15,A15,"ElectricalEquipDef") -> NCC S35C2lNREL 956/Eley AnalysisClass 9a clinic/day surgery/procedure unit; radiant/latent/lost fraction split retained from original WA/COMNET-REV9 source (AIRAH Technical Handbook does not publish this split)BA Healthcare ClinicElectricalEquipDef | BA15: NECB-A-Electric-Equipment | BB15: 0.418064 | BC15: 4.5 | BD15: 0.37 | BE15: 0.2 | BF15: NCC J7D3a | BH15: Health-care - examination room; radiant/visible fraction split retained from original WA/COMNET-REV9 source (AIRAH Technical Handbook does not publish this split) | BI15: =CONCATENATE(BF15,BG15,BH15,"LightingDef") -> NCC J7D3aHealth-care - examination room; radiant/visible fraction split retained from original WA/COMNET-REV9 source (AIRAH Technical Handbook does not publish this split)LightingDef | BJ15: NECB-A-Lighting | BK15: 0.3312242 | BL15: 1.130137 | BM15: 12.164795 | BN15: 0 | BO15: 0 | BP15: 0.5 | BQ15: COMNET-REV9 | BR15: California Commercial End-Use Survey (CEUS) | BS15: DOEPrototype | BT15: =CONCATENATE(BQ15,BR15,BS15,A15,"GasEquipDef") -> COMNET-REV9California Commercial End-Use Survey (CEUS)DOEPrototypeBA Healthcare ClinicGasEquipDef | BU15: OutPatientHealthCare BLDG_EQUIP_SCH_BASE | BW15: 0.7 | BY15: NCC S34C2(6) | BZ15: 0.7 ACH assumed as design infiltration for periods without mechanical outdoor air supply; NCC also specifies 0.35 ACH when mechanical OA is operating (to be applied via infiltration schedule once developed) | CB15: =CONCATENATE(CE15,"_",CF15) -> Health-care clinic_WholeBuilding | CC15: =CONCATENATE(BY15,BZ15,A15,"Infil") -> NCC S34C2(6)0.7 ACH assumed as design infiltration for periods without mechanical outdoor air supply; NCC also specifies 0.35 ACH when mechanical OA is operating (to be applied via infiltration schedule once developed)BA Healthcare ClinicInfil | CD15: Always On | CE15: Health-care clinic | CF15: WholeBuilding | CH15: 2 | CJ15: MediumSmooth | CK15: 0.15 | CL15: 0.12 | CM15: 540 | CN15: 1210 | CO15: 0.9 | CP15: 0.7 | CQ15: 0.7 | CR15: Std Wood 6inch | CS15: OpenStudio-Prototype-Buildings | CV15: =CR15 -> Std Wood 6inch | CW15: =CONCATENATE(CS15,CT15,CU15,CV15,"InternalMassDef") -> OpenStudio-Prototype-BuildingsStd Wood 6inchInternalMassDef
A16: BA Hospital | B16: =CONCATENATE(F16,"_",G16,"_",H16) -> 2025_AU_NCC | C16: =MID(A16,4,80) -> Hospital | D16: Whole Building | E16: WholeBuilding | F16: 2025 | G16: AU | H16: NCC | I16: 255 | J16: 255 | K16: 255 | L16: =CONCATENATE(A16,"_",F16,G16,H16) -> BA Hospital_2025AUNCC | M16: =CONCATENATE(L16,"ScheduleSet") -> BA Hospital_2025AUNCCScheduleSet | N16: 200 | O16: 5 | P16: 0.053819575 | Q16: 255.91 | R16: 75 | S16: 187.67 | T16: 55 | W16: 130 | X16: 0.57692308 | Y16: NCC S35C2n | Z16: Other applications (non-dining) | AC16: =CONCATENATE(Y16,Z16,AA16,AB16,A16,"PeopleDef") -> NCC S35C2nOther applications (non-dining)BA HospitalPeopleDef | AD16: NECB-H-Occupancy | AE16: =CONCATENATE(A16,"Activity") -> BA HospitalActivity | AH16: 0.47 | AI16: =AH16*0.00508 -> 0.0023876 | AM16: COMNET-REV9 | AN16: WholeBuilding | AQ16: =CONCATENATE(AM16,AN16,AO16,AP16,A16,"Vent") -> COMNET-REV9WholeBuildingBA HospitalVent | AR16: 0.464515 | AS16: 5 | AT16: 0 | AU16: 0.5 | AV16: 0 | AW16: NCC S35C2l | AX16: NREL 956/Eley Analysis | AY16: Class 9a ward area (whole-building composite default); radiant/latent/lost fraction split retained from original WA/COMNET-REV9 source (AIRAH Technical Handbook does not publish this split) | AZ16: =CONCATENATE(AW16,AX16,AY16,A16,"ElectricalEquipDef") -> NCC S35C2lNREL 956/Eley AnalysisClass 9a ward area (whole-building composite default); radiant/latent/lost fraction split retained from original WA/COMNET-REV9 source (AIRAH Technical Handbook does not publish this split)BA HospitalElectricalEquipDef | BA16: NECB-H-Electric-Equipment | BB16: 0.232258 | BC16: 2.5 | BD16: 0.37 | BE16: 0.2 | BF16: NCC J7D3a | BH16: Health-care - all other patient care areas including wards and corridors; radiant/visible fraction split retained from original WA/COMNET-REV9 source (AIRAH Technical Handbook does not publish this split) | BI16: =CONCATENATE(BF16,BG16,BH16,"LightingDef") -> NCC J7D3aHealth-care - all other patient care areas including wards and corridors; radiant/visible fraction split retained from original WA/COMNET-REV9 source (AIRAH Technical Handbook does not publish this split)LightingDef | BJ16: NECB-H-Lighting | BK16: 0.3312242 | BL16: 1.130137 | BM16: 12.164795 | BN16: 0.01 | BO16: 0.2 | BP16: 0.7 | BQ16: COMNET-REV9 | BR16: California Commercial End-Use Survey (CEUS) | BS16: DOEPrototype | BT16: =CONCATENATE(BQ16,BR16,BS16,A16,"GasEquipDef") -> COMNET-REV9California Commercial End-Use Survey (CEUS)DOEPrototypeBA HospitalGasEquipDef | BU16: Hospital BLDG_EQUIP_SCH | BW16: 0.7 | BY16: NCC S34C2(6) | BZ16: 0.7 ACH assumed as design infiltration for periods without mechanical outdoor air supply; NCC also specifies 0.35 ACH when mechanical OA is operating (to be applied via infiltration schedule once developed) | CB16: =CONCATENATE(CE16,"_",CF16) -> Hospital_WholeBuilding | CC16: =CONCATENATE(BY16,BZ16,A16,"Infil") -> NCC S34C2(6)0.7 ACH assumed as design infiltration for periods without mechanical outdoor air supply; NCC also specifies 0.35 ACH when mechanical OA is operating (to be applied via infiltration schedule once developed)BA HospitalInfil | CD16: Always On | CE16: Hospital | CF16: WholeBuilding | CH16: 2 | CJ16: MediumSmooth | CK16: 0.15 | CL16: 0.12 | CM16: 540 | CN16: 1210 | CO16: 0.9 | CP16: 0.7 | CQ16: 0.7 | CR16: Std Wood 6inch | CS16: OpenStudio-Prototype-Buildings | CV16: =CR16 -> Std Wood 6inch | CW16: =CONCATENATE(CS16,CT16,CU16,CV16,"InternalMassDef") -> OpenStudio-Prototype-BuildingsStd Wood 6inchInternalMassDef
... A23: BA Museum | B23: =CONCATENATE(F23,"_",G23,"_",H23) -> 2025_AU_NCC | C23: =MID(A23,4,80) -> Museum | D23: Whole Building | E23: WholeBuilding | F23: 2025 | G23: AU | H23: NCC | I23: 255 | J23: 255 | K23: 255 | L23: =CONCATENATE(A23,"_",F23,G23,H23) -> BA Museum_2025AUNCC | M23: =CONCATENATE(L23,"ScheduleSet") -> BA Museum_2025AUNCCScheduleSet | N23: 25 | O23: 40 | P23: 0.4305566 | Q23: 255.91 | R23: 75 | S23: 187.67 | T23: 55 | W23: 130 | X23: 0.57692308 | Y23: NCC S35C2n | Z23: Other applications (non-dining) | AC23: =CONCATENATE(Y23,Z23,AA23,AB23,A23,"PeopleDef") -> NCC S35C2nOther applications (non-dining)BA MuseumPeopleDef | AD23: NECB-C-Occupancy | AE23: =CONCATENATE(A23,"Activity") -> BA MuseumActivity | AH23: 0.36 | AI23: =AH23*0.00508 -> 0.0018288 | AM23: COMNET-REV9 | AN23: WholeBuilding | AQ23: =CONCATENATE(AM23,AN23,AO23,AP23,A23,"Vent") -> COMNET-REV9WholeBuildingBA MuseumVent | AR23: 0 | AS23: 0 | AT23: 0 | AU23: 0.5 | AV23: 0 | AW23: NCC S35C2l | AX23: NREL 956/Eley Analysis | AY23: Class 9b (Other applications) - no equipment load per S35C2l; radiant/latent/lost fraction split retained from original WA/COMNET-REV9 source (AIRAH Technical Handbook does not publish this split) | AZ23: =CONCATENATE(AW23,AX23,AY23,A23,"ElectricalEquipDef") -> NCC S35C2lNREL 956/Eley AnalysisClass 9b (Other applications) - no equipment load per S35C2l; radiant/latent/lost fraction split retained from original WA/COMNET-REV9 source (AIRAH Technical Handbook does not publish this split)BA MuseumElectricalEquipDef | BA23: NECB-C-Electric-Equipment | BB23: 0.232258 | BC23: 2.5 | BD23: 0.37 | BE23: 0.2 | BF23: NCC J7D3a | BH23: Museum and gallery - circulation, cleaning and service lighting; radiant/visible fraction split retained from original WA/COMNET-REV9 source (AIRAH Technical Handbook does not publish this split) | BI23: =CONCATENATE(BF23,BG23,BH23,"LightingDef") -> NCC J7D3aMuseum and gallery - circulation, cleaning and service lighting; radiant/visible fraction split retained from original WA/COMNET-REV9 source (AIRAH Technical Handbook does not publish this split)LightingDef | BJ23: NECB-C-Lighting | BK23: 0.006691398 | BL23: 0.02283105 | BM23: 0.24575342 | BN23: 0 | BO23: 0.75 | BP23: 0.25 | BQ23: COMNET-REV9 | BR23: California Commercial End-Use Survey (CEUS) | BS23: 93%ThermEffRadiant | BT23: =CONCATENATE(BQ23,BR23,BS23,A23,"GasEquipDef") -> COMNET-REV9California Commercial End-Use Survey (CEUS)93%ThermEffRadiantBA MuseumGasEquipDef | BU23: NECB-A-Electric-Equipment | BW23: 0.7 | BY23: NCC S34C2(6) | BZ23: 0.7 ACH assumed as design infiltration for periods without mechanical outdoor air supply; NCC also specifies 0.35 ACH when mechanical OA is operating (to be applied via infiltration schedule once developed) | CB23: =CONCATENATE(CE23,"_",CF23) -> Museum_WholeBuilding | CC23: =CONCATENATE(BY23,BZ23,A23,"Infil") -> NCC S34C2(6)0.7 ACH assumed as design infiltration for periods without mechanical outdoor air supply; NCC also specifies 0.35 ACH when mechanical OA is operating (to be applied via infiltration schedule once developed)BA MuseumInfil | CD23: Always On | CE23: Museum | CF23: WholeBuilding | CH23: 2 | CJ23: MediumSmooth | CK23: 0.15 | CL23: 0.12 | CM23: 540 | CN23: 1210 | CO23: 0.9 | CP23: 0.7 | CQ23: 0.7 | CR23: Std Wood 6inch | CS23: OpenStudio-Prototype-Buildings | CV23: =CR23 -> Std Wood 6inch | CW23: =CONCATENATE(CS23,CT23,CU23,CV23,"InternalMassDef") -> OpenStudio-Prototype-BuildingsStd Wood 6inchInternalMassDef
A24: BA Office | B24: =CONCATENATE(F24,"_",G24,"_",H24) -> 2025_AU_NCC | C24: =MID(A24,4,80) -> Office | D24: Whole Building | E24: WholeBuilding | F24: 2025 | G24: AU | H24: NCC | I24: 255 | J24: 255 | K24: 255 | L24: =CONCATENATE(A24,"_",F24,G24,H24) -> BA Office_2025AUNCC | M24: =CONCATENATE(L24,"ScheduleSet") -> BA Office_2025AUNCCScheduleSet | N24: 200 | O24: 5 | P24: 0.053819575 | Q24: 255.91 | R24: 75 | S24: 187.67 | T24: 55 | W24: 130 | X24: 0.57692308 | Y24: NCC S35C2n | Z24: Class 5 (Office) - Other applications (non-dining) | AC24: =CONCATENATE(Y24,Z24,AA24,AB24,A24,"PeopleDef") -> NCC S35C2nClass 5 (Office) - Other applications (non-dining)BA OfficePeopleDef | AD24: NECB-A-Occupancy | AE24: =CONCATENATE(A24,"Activity") -> BA OfficeActivity | AH24: 0.09 | AI24: =AH24*0.00508 -> 0.0004572 | AM24: COMNET-REV9 | AN24: WholeBuilding | AQ24: =CONCATENATE(AM24,AN24,AO24,AP24,A24,"Vent") -> COMNET-REV9WholeBuildingBA OfficeVent | AR24: 1.021933 | AS24: 11 | AT24: 0 | AU24: 0.5 | AV24: 0 | AW24: NCC S35C2l | AX24: COMNET-REV9 | AY24: NCC S35C2l for equipment W/m2; radiant/latent/lost fraction split retained from original WA/COMNET-REV9 source (AIRAH Technical Handbook does not publish this split) | AZ24: =CONCATENATE(AW24,AX24,AY24,A24,"ElectricalEquipDef") -> NCC S35C2lCOMNET-REV9NCC S35C2l for equipment W/m2; radiant/latent/lost fraction split retained from original WA/COMNET-REV9 source (AIRAH Technical Handbook does not publish this split)BA OfficeElectricalEquipDef | BA24: NECB-A-Electric-Equipment | BB24: 0.418064 | BC24: 4.5 | BD24: 0.37 | BE24: 0.2 | BF24: NCC J7D3a | BG24: COMNET-REV9 | BH24: NCC J7D3a for lighting W/m2 (office >= 200 lux row); radiant/visible fraction split retained from original WA/COMNET-REV9 source (AIRAH Technical Handbook does not publish this split) | BI24: =CONCATENATE(BF24,BG24,BH24,"LightingDef") -> NCC J7D3aCOMNET-REV9NCC J7D3a for lighting W/m2 (office >= 200 lux row); radiant/visible fraction split retained from original WA/COMNET-REV9 source (AIRAH Technical Handbook does not publish this split)LightingDef | BJ24: NECB-A-Lighting | BK24: 0 | BL24: 0 | BM24: 0 | BN24: 0 | BO24: 0 | BP24: 0 | BQ24: N/A | BS24: No gas appliances assumed for Class 5 office; consistent with NCC Spec 35 (no gas equipment profile modelled for offices) | BT24: =CONCATENATE(BQ24,BR24,BS24,A24,"GasEquipDef") -> N/ANo gas appliances assumed for Class 5 office; consistent with NCC Spec 35 (no gas equipment profile modelled for offices)BA OfficeGasEquipDef | BU24: OfficeMedium BLDG_EQUIP_SCH | BW24: 0.7 | BY24: NCC S34C2(6) | BZ24: 0.7 ACH assumed as design infiltration for periods without mechanical outdoor air supply; NCC also specifies 0.35 ACH when mechanical OA is operating (to be applied via infiltration schedule once developed) | CB24: =CONCATENATE(CE24,"_",CF24) -> Office_WholeBuilding | CC24: =CONCATENATE(BY24,BZ24,A24,"Infil") -> NCC S34C2(6)0.7 ACH assumed as design infiltration for periods without mechanical outdoor air supply; NCC also specifies 0.35 ACH when mechanical OA is operating (to be applied via infiltration schedule once developed)BA OfficeInfil | CD24: Always On | CE24: Office | CF24: WholeBuilding | CH24: 2 | CJ24: MediumSmooth | CK24: 0.15 | CL24: 0.12 | CM24: 540 | CN24: 1210 | CO24: 0.9 | CP24: 0.7 | CQ24: 0.7 | CR24: Std Wood 6inch | CS24: OpenStudio-Prototype-Buildings | CV24: =CR24 -> Std Wood 6inch | CW24: =CONCATENATE(CS24,CT24,CU24,CV24,"InternalMassDef") -> OpenStudio-Prototype-BuildingsStd Wood 6inchInternalMassDef
